<?xml version="1.0" ?>
<!-- =================================================================================== -->
<!-- |    This document was autogenerated by xacro from farmbot.xacro                  | -->
<!-- |    EDITING THIS FILE BY HAND IS NOT RECOMMENDED                                 | -->
<!-- =================================================================================== -->
<robot name="farmbot">
  <!-- Base link -->
  <link name="farmbot_base_link">
    <visual>
      <origin rpy="0 0 0" xyz="0 0 0.1"/>
      <geometry>
        <box size="1.0 0.6 0.2"/>
      </geometry>
      <material name="blue">
        <color rgba="0.0 0.0 1.0 1.0"/>
      </material>
    </visual>
    <collision>
      <origin rpy="0 0 0" xyz="0 0 0.1"/>
      <geometry>
        <box size="1.0 0.6 0.2"/>
      </geometry>
    </collision>
    <inertial>
      <mass value="50.0"/>
      <inertia ixx="1.0" ixy="0.0" ixz="0.0" iyy="1.0" iyz="0.0" izz="1.0"/>
    </inertial>
  </link>
  <link name="farmbot_front_left_steer_link">
    <visual>
      <geometry>
        <box size="0.1 0.1 0.05"/>
      </geometry>
      <material name="gray">
        <color rgba="0.5 0.5 0.5 1.0"/>
      </material>
    </visual>
    <collision>
      <geometry>
        <box size="0.1 0.1 0.05"/>
      </geometry>
    </collision>
    <inertial>
      <mass value="1.0"/>
      <inertia ixx="0.01" ixy="0.0" ixz="0.0" iyy="0.01" iyz="0.0" izz="0.01"/>
    </inertial>
  </link>
  <joint name="farmbot_front_left_steer_joint" type="revolute">
    <parent link="farmbot_base_link"/>
    <child link="farmbot_front_left_steer_link"/>
    <origin rpy="0 0 0" xyz="0.4 0.3 0"/>
    <axis xyz="0 0 1"/>
    <limit effort="100" lower="-1.57" upper="1.57" velocity="1.0"/>
  </joint>
  <link name="farmbot_front_left_wheel_link">
    <visual>
      <geometry>
        <cylinder length="0.1" radius="0.2"/>
      </geometry>
      <material name="black">
        <color rgba="0.0 0.0 0.0 1.0"/>
      </material>
    </visual>
    <collision>
      <geometry>
        <cylinder length="0.1" radius="0.2"/>
      </geometry>
    </collision>
    <inertial>
      <mass value="5.0"/>
      <inertia ixx="0.1" ixy="0.0" ixz="0.0" iyy="0.1" iyz="0.0" izz="0.1"/>
    </inertial>
  </link>
  <joint name="farmbot_front_left_wheel_joint" type="continuous">
    <parent link="farmbot_front_left_steer_link"/>
    <child link="farmbot_front_left_wheel_link"/>
    <origin rpy="0 0 0" xyz="0 0 -0.1"/>
    <axis xyz="0 0 1"/>
  </joint>
  <link name="farmbot_front_right_steer_link">
    <visual>
      <geometry>
        <box size="0.1 0.1 0.05"/>
      </geometry>
      <material name="gray">
        <color rgba="0.5 0.5 0.5 1.0"/>
      </material>
    </visual>
    <collision>
      <geometry>
        <box size="0.1 0.1 0.05"/>
      </geometry>
    </collision>
    <inertial>
      <mass value="1.0"/>
      <inertia ixx="0.01" ixy="0.0" ixz="0.0" iyy="0.01" iyz="0.0" izz="0.01"/>
    </inertial>
  </link>
  <joint name="farmbot_front_right_steer_joint" type="revolute">
    <parent link="farmbot_base_link"/>
    <child link="farmbot_front_right_steer_link"/>
    <origin rpy="0 0 0" xyz="0.4 -0.3 0"/>
    <axis xyz="0 0 1"/>
    <limit effort="100" lower="-1.57" upper="1.57" velocity="1.0"/>
  </joint>
  <link name="farmbot_front_right_wheel_link">
    <visual>
      <geometry>
        <cylinder length="0.1" radius="0.2"/>
      </geometry>
      <material name="black">
        <color rgba="0.0 0.0 0.0 1.0"/>
      </material>
    </visual>
    <collision>
      <geometry>
        <cylinder length="0.1" radius="0.2"/>
      </geometry>
    </collision>
    <inertial>
      <mass value="5.0"/>
      <inertia ixx="0.1" ixy="0.0" ixz="0.0" iyy="0.1" iyz="0.0" izz="0.1"/>
    </inertial>
  </link>
  <joint name="farmbot_front_right_wheel_joint" type="continuous">
    <parent link="farmbot_front_right_steer_link"/>
    <child link="farmbot_front_right_wheel_link"/>
    <origin rpy="0 0 0" xyz="0 0 -0.1"/>
    <axis xyz="0 0 1"/>
  </joint>
  <link name="farmbot_rear_left_steer_link">
    <visual>
      <geometry>
        <box size="0.1 0.1 0.05"/>
      </geometry>
      <material name="gray">
        <color rgba="0.5 0.5 0.5 1.0"/>
      </material>
    </visual>
    <collision>
      <geometry>
        <box size="0.1 0.1 0.05"/>
      </geometry>
    </collision>
    <inertial>
      <mass value="1.0"/>
      <inertia ixx="0.01" ixy="0.0" ixz="0.0" iyy="0.01" iyz="0.0" izz="0.01"/>
    </inertial>
  </link>
  <joint name="farmbot_rear_left_steer_joint" type="revolute">
    <parent link="farmbot_base_link"/>
    <child link="farmbot_rear_left_steer_link"/>
    <origin rpy="0 0 0" xyz="-0.4 0.3 0"/>
    <axis xyz="0 0 1"/>
    <limit effort="100" lower="-1.57" upper="1.57" velocity="1.0"/>
  </joint>
  <link name="farmbot_rear_left_wheel_link">
    <visual>
      <geometry>
        <cylinder length="0.1" radius="0.2"/>
      </geometry>
      <material name="black">
        <color rgba="0.0 0.0 0.0 1.0"/>
      </material>
    </visual>
    <collision>
      <geometry>
        <cylinder length="0.1" radius="0.2"/>
      </geometry>
    </collision>
    <inertial>
      <mass value="5.0"/>
      <inertia ixx="0.1" ixy="0.0" ixz="0.0" iyy="0.1" iyz="0.0" izz="0.1"/>
    </inertial>
  </link>
  <joint name="farmbot_rear_left_wheel_joint" type="continuous">
    <parent link="farmbot_rear_left_steer_link"/>
    <child link="farmbot_rear_left_wheel_link"/>
    <origin rpy="0 0 0" xyz="0 0 -0.1"/>
    <axis xyz="0 0 1"/>
  </joint>
  <link name="farmbot_rear_right_steer_link">
    <visual>
      <geometry>
        <box size="0.1 0.1 0.05"/>
      </geometry>
      <material name="gray">
        <color rgba="0.5 0.5 0.5 1.0"/>
      </material>
    </visual>
    <collision>
      <geometry>
        <box size="0.1 0.1 0.05"/>
      </geometry>
    </collision>
    <inertial>
      <mass value="1.0"/>
      <inertia ixx="0.01" ixy="0.0" ixz="0.0" iyy="0.01" iyz="0.0" izz="0.01"/>
    </inertial>
  </link>
  <joint name="farmbot_rear_right_steer_joint" type="revolute">
    <parent link="farmbot_base_link"/>
    <child link="farmbot_rear_right_steer_link"/>
    <origin rpy="0 0 0" xyz="-0.4 -0.3 0"/>
    <axis xyz="0 0 1"/>
    <limit effort="100" lower="-1.57" upper="1.57" velocity="1.0"/>
  </joint>
  <link name="farmbot_rear_right_wheel_link">
    <visual>
      <geometry>
        <cylinder length="0.1" radius="0.2"/>
      </geometry>
      <material name="black">
        <color rgba="0.0 0.0 0.0 1.0"/>
      </material>
    </visual>
    <collision>
      <geometry>
        <cylinder length="0.1" radius="0.2"/>
      </geometry>
    </collision>
    <inertial>
      <mass value="5.0"/>
      <inertia ixx="0.1" ixy="0.0" ixz="0.0" iyy="0.1" iyz="0.0" izz="0.1"/>
    </inertial>
  </link>
  <joint name="farmbot_rear_right_wheel_joint" type="continuous">
    <parent link="farmbot_rear_right_steer_link"/>
    <child link="farmbot_rear_right_wheel_link"/>
    <origin rpy="0 0 0" xyz="0 0 -0.1"/>
    <axis xyz="0 0 1"/>
  </joint>
</robot>
